Workbook

Sheet SUMMARY & COST DISTRIBUTION
A16: NESTURA DESIGNS (formerly SA INTERIOR SCAPES)
A17: SUMMARY
A18: Client Name | B18: Pratichi behera
A19: Requirement | B19: 2 BHK
A20: Property Type | B20: Flat
A21: Property Age | B21: New
A22: Location | B22: VTP Sierra, Sus
A23: Quotation by | B23: Aishwarya Khinvasara
A24: Date | B24: =TODAY() -> 9/11/2026
A28: Project Cost Distrubution
A30: [A] Furniture Works Costs
A61: Area/Room | B61: Cost
A62: ='DETAILED ESTIMATE'!B4 -> ENTRANCE FOYER AREA | B62: ='DETAILED ESTIMATE'!J13 -> ₹ 40,200
A63: ='DETAILED ESTIMATE'!B15 -> LIVING AREA | B63: ='DETAILED ESTIMATE'!J26 -> ₹ 121,200
A64: ='DETAILED ESTIMATE'!B28 -> BALCONY | B64: ='DETAILED ESTIMATE'!J34 -> ₹ 40,500
A65: ='DETAILED ESTIMATE'!B36 -> KITCHEN | B65: ='DETAILED ESTIMATE'!J49 -> ₹ 486,800
A66: ='DETAILED ESTIMATE'!B51 -> FIRST GUEST BEDROOM | B66: ='DETAILED ESTIMATE'!J68 -> ₹ 167,500
A67: ='DETAILED ESTIMATE'!B70 -> SECOND KIDS BEDROOM | B67: ='DETAILED ESTIMATE'!J83 -> ₹ 178,380
A68: ='DETAILED ESTIMATE'!B85 -> BATHROOM (COMMON ROOM) | B68: ='DETAILED ESTIMATE'!J92 -> ₹ 0
A69: ='DETAILED ESTIMATE'!B94 -> THIRD MASTER BEDROOM | B69: ='DETAILED ESTIMATE'!J105 -> ₹ 272,440
A70: * Actual cost of all items above may change as per actuals
A71: Furniture Works Total | B71: =SUM(B62:B70) -> ₹ 1,307,020
A74: [B] Other Works Cost
A103: Item | B103: Cost
A104: ='DETAILED ESTIMATE'!B109 -> FALSE CEILING WORK | B104: ='DETAILED ESTIMATE'!J126 -> ₹ 77,378
A105: ='DETAILED ESTIMATE'!B128 -> PAINTING & WALL FINISHES | B105: ='DETAILED ESTIMATE'!J144 -> ₹ 122,000
A106: ='DETAILED ESTIMATE'!B146 -> ELECTRICAL WORK | B106: ='DETAILED ESTIMATE'!J159 -> ₹ 92,900
A107: ='DETAILED ESTIMATE'!B161 -> AIR- CONDITIONING WORK | B107: ='DETAILED ESTIMATE'!J166 -> ₹ 0
A108: ='DETAILED ESTIMATE'!B168 -> PLUMBING WORK | B108: ='DETAILED ESTIMATE'!J174 -> ₹ 35,000
A109: ='DETAILED ESTIMATE'!B176 -> CIVIL WORK | B109: ='DETAILED ESTIMATE'!J189 -> ₹ 74,800
A110: ='DETAILED ESTIMATE'!B191 -> FABRICATION WORK | B110: ='DETAILED ESTIMATE'!J201 -> ₹ 0
A111: ='DETAILED ESTIMATE'!B203 -> FABRICS AND STICHING | B111: ='DETAILED ESTIMATE'!J217 -> ₹ 90,900
A112: ='DETAILED ESTIMATE'!B219 -> BOUGHT OUT ITEMS (subject to selection) | B112: ='DETAILED ESTIMATE'!J232 -> ₹ 227,000
A113: ='DETAILED ESTIMATE'!B234 -> MISCELLANEOUS ITEMS (subject to selection) | B113: ='DETAILED ESTIMATE'!J246 -> ₹ 8,000
A114: * Actual cost of all items above may change as per actuals
A115: Other Works Total | B115: =SUM(B104:B113) -> ₹ 727,978
A117: Total Project Cost
A118: [A] Furnitue Works Total | B118: =B71 -> ₹ 1,307,020
A119: [B] Other Works Total | B119: =B115 -> ₹ 727,978
A120: [C] Project Cost (A + B) | B120: =B118+B119 -> ₹ 2,034,998
...

Sheet DETAILED ESTIMATE
A1: NESTURA DESIGNS (formerly SA INTERIOR SCAPES)
A2: DETAILED ESTIMATE
A3: S.NO | B3: ITEM | C3: PROPOSED DETAILS/MATERIALS | D3: LENGTH | E3: BREADTH | F3: NO.S | G3: QUANTITY (APPROX) | H3: UNITS | I3: RATE | J3: GRAND TOTAL
A4: A | B4: ENTRANCE FOYER AREA
A6: 1 | B6: SAFTEY DOOR | C6: a)Safety Door with Metal Grill and Godgrej Lock | D6: 7.5 | E6: 3 | F6: 1 | G6: =F6*E6*D6 -> 22.5 | H6: sq.ft | I6: 1850 | J6: NA
A7: 2 | B7: MAIN DOOR | C7: a) flush door saftey door.(Finish - Matt finish ) (Open style - Hinged/Swing/Sliding) handles and b)locks cost subject to selection as per desgin | D7: 7.3 | E7: 3.6 | F7: 1 | G7: =F7*E7*D7 -> 26.28 | H7: sq.ft | I7: 1800 | J7: NA
A8: 3 | B8: ENTRANCE DESIGNER PANEL | C8: a) name plate with paneling of plywood | D8: 7 | E8: 9 | F8: 1 | G8: 72 | H8: sq.ft | I8: 800 | J8: NA
A9: 4 | B9: SHOE RACK | C9: a) plywood shoe rack with laminate finish. | D9: 4 | E9: 4 | F9: 1 | G9: =F9*E9*D9 -> 16 | H9: sq.ft | I9: 2200 | J9: =I9*G9 -> ₹ 35,200.00
A10: 6 | B10: NAME PLATE | C10: a) name plate with paneling of plywood | D10: 2 | E10: 2 | F10: 1 | G10: =F10*E10*D10 -> 4 | H10: sq.ft | I10: LUMPSUM | J10: 5000
A11: 6 | B11: FOYER WALL WITH PANELING | C11: paneling of plywood | D11: 4.5 | E11: 6 | F11: 1 | G11: =F11*E11*D11 -> 27 | H11: sq.ft | I11: 800 | J11: NA
A13: TOTAL OF ENTRANCE FOYER AREA | J13: =SUM(J6:J10) -> ₹ 40,200.00
A15: B | B15: LIVING AREA
A16: 1 | B16: TV UNIT DESIGNER PANELLING | C16: Left Size Wall Panel with shelves a) Providing & making of 2" thk paneling.Framework and 8mm thk . ply treated with LAMINATE AND WALL PAPER | D16: 5 | E16: 9 | F16: 1 | G16: =F16*E16*D16 -> 45 | H16: sq.ft | I16: 1000 | J16: =I16*G16 -> ₹ 45,000.00
A17: 2 | B17: BOOK SHELF | C17: b) 18mm plywood With Dark Walnut laminate with 2 drawers | D17: 7 | E17: 5 | F17: 1 | G17: =F17*E17*D17 -> 35 | H17: sq.ft | I17: 1800 | J17: NA
A18: 3 | B18: TV UNIT LEDGE | C18: b) 18mm plywood With Dark Walnut laminate with 2 drawers | D18: 5 | E18: 1.8 | F18: 1 | G18: =F18*E18*D18 -> 9 | H18: sq.ft | I18: 1800 | J18: =I18*G18 -> ₹ 16,200.00
A19: 4 | B19: DINING TABLE | C19: a) Material - plywood | D19: 6 | E19: 4 | F19: 1 | G19: =F19*E19*D19 -> 24 | H19: sq.ft | I19: 1800 | J19: =I19*G19 -> ₹ 43,200.00
A20: 5 | B20: DESIGNER PANELLING | C20: Sofa Back Wall Panelling with Wall Light | D20: 4 | E20: 9 | F20: 1 | G20: =F20*E20*D20 -> 36 | H20: sq.ft | I20: 900 | J20: NA
A21: 5 | B21: DESIGNER PANELLING | C21: Sofa Back Wall - Moulding integrated in pop | D21: 3 | E21: 7 | F21: 1 | G21: =F21*E21*D21 -> 21 | H21: sq.ft | I21: 800 | J21: =I21*G21 -> ₹ 16,800.00
A22: 6 | B22: AC PANELLING | C22: a) Providing designer wall | D22: 2 | E22: 18.6 | F22: 1 | G22: =F22*E22*D22 -> 37.2 | H22: sq.ft | I22: 900 | J22: NA
A23: 7 | B23: STORAGE ON DININNG WAL | C23: b) 18mm plywood With Dark Walnut laminate with 2 drawers and profile glass shutters | D23: 2 | E23: 5 | F23: 1 | G23: =F23*E23*D23 -> 10 | H23: sq.ft | I23: 1800 | J23: NA
A24: 8 | B24: MANDIR | C24: a) Providing and making a fluted glass mandir unit - Ihs with thin profile aluminum sections in black powder coated inside treated with 1 mm thk app shade of laminate with 4 nos of drawers & 1 nos. of 12 mm thk clear white glass shelf (basic cost of laminate upto Rs. 1500/- sheet) | D24: 3 | E24: 4 | F24: 1 | G24: =F24*E24*D24 -> 12 | H24: sq.ft | I24: 2100 | J24: =I24*G24 -> ₹ 25,200.00
A26: TOTAL OF LIVING AREA | J26: =SUM(J16:J23) -> ₹ 121,200.00
A28: C | B28: BALCONY
A29: 1 | B29: DESIGNER PANELLING | C29: Designer dado tiles with fitting | D29: 5 | E29: 9 | F29: 1 | G29: =F29*E29*D29 -> 45 | H29: sq.ft | I29: 900 | J29: =I29*G29 -> ₹ 40,500.00
A30: 2 | B30: SEATING/SWING | C30: a)granite top b) 18mm plywood With Dark Walnut laminate | D30: 2 | E30: 5 | F30: 1 | G30: =F30*E30*D30 -> 10 | H30: sq.ft | I30: 2100 | J30: NA
A31: 3 | B31: JANITER STORAGE | C31: b) 18mm plywood With Dark Walnut laminate | D31: 1 | E31: 7 | F31: 1 | G31: =F31*E31*D31 -> 7 | H31: sq.ft | I31: 1800 | J31: NA
A32: 4 | B32: OUTDOOR CHAIR AND COFFEE TABLE SET | C32: 2 Chairs and table | G32: 1 | H32: sq.ft | I32: 15000 | J32: NA
A34: TOTAL OF BALCONY AREA | J34: =SUM(J29:J32) -> ₹ 40,500.00
A36: D | B36: KITCHEN
A38: 1 | B38: KITCHEN TANDOMS | C38: a) Pre-laminated HDHMR/ BWP plywood withACRELIC lamination b)tandem hardware of EBCO BRAND 10TANDOMS | D38: 12 | E38: 3 | F38: 1 | G38: =F38*E38*D38 -> 36 | H38: sq.ft | I38: 6000 | J38: =I38*G38 -> ₹ 216,000.00
A39: 1 | B39: KITCHEN SHUTTERS | C39: a) Pre-laminated HDHMR/ BWP plywood with lamination b)tandem hardware of ebco brand | D39: 6 | E39: 3 | F39: 1 | G39: =F39*E39*D39 -> 18 | H39: sq.ft | I39: 3500 | J39: =I39*G39 -> ₹ 63,000.00
A40: 2 | B40: Over Counter Around Chimney ( Profile Doors + Acryilic laminate | C40: a) Providing and making a over head Storage made out of 19mm thk .Ply & finished in 1 mm thk approved laminate from both sides with ss rack onths.(basic cost of laminate upto Rs. 1500sheet.)(With necessary hardware like hinges, handles,lock,etc) as pes design | D40: 18 | E40: 2 | F40: 1 | G40: =F40*E40*D40 -> 36 | H40: sq.ft | I40: 2100 | J40: =I40*G40 -> ₹ 75,600.00
A41: 3 | B41: LOFT STORAGE | C41: a) Providing and making a over head Storage made out of 19mm thk .Ply & finished in 1 mm thk approved laminate (basic cost of laminate upto Rs. 1500sheet.)(With necessary hardware like hinges, handles,lock,etc) as pes design | D41: 18 | E41: 2 | F41: 1 | G41: =F41*E41*D41 -> 36 | H41: sq.ft | I41: 1800 | J41: =I41*G41 -> ₹ 64,800.00
A42: 4 | B42: APPLIANCESTORAGE /ROLLING SHUTTER | C42: a) HDHMR / bwp with laminate .Providing and making a Full ht Storage made out of 19mm thk .Ply & finished in 1 mm thk approved laminate from both sides.(basic cost of laminate upto Rs. 1500/-sheet.)(With necessary hardware like hinges handles.lock etc) | D42: 2 | E42: 5 | F42: 1 | G42: =F42*E42*D42 -> 10 | H42: sq.ft | I42: 3500 | J42: =I42*G42 -> ₹ 35,000.00
A43: 5 | B43: BREAKFAST COUNTER | C43: a) HDHMR / bwp with laminate .Providing and making a Full ht Storage made out of 19mm thk .Ply & finished in 1 mm thk approved laminate from both sides.(basic cost of laminate upto Rs. 1500/-sheet.)(With necessary hardware like hinges handles.lock etc) | D43: 4 | E43: 4 | F43: 1 | G43: =F43*E43*D43 -> 16 | H43: sq.ft | I43: 2200 | J43: NA
A44: 5 | B44: KITCHEN PANTRY | C44: a) HDHMR / bwp with laminate .Providing and making a Full ht Storage made out of 19mm thk .Ply & finished in 1 mm thk approved laminate from both sides.(basic cost of laminate upto Rs. 1500/-sheet.)(With necessary hardware like hinges handles.lock etc) | D44: 1.5 | E44: 7 | F44: 1 | G44: =F44*E44*D44 -> 10.5 | H44: sq.ft | I44: 4500 | J44: NA
A45: 6 | B45: DRY BALCONY STORAGE | C45: a) WPC dry balcony storage | D45: 3 | E45: 3 | F45: 2 | G45: =F45*E45*D45 -> 18 | H45: sq.ft | I45: 1800 | J45: =I45*G45 -> ₹ 32,400.00
A46: 7 | B46: SLIDING DOOR | C46: a) Providing & making kitchen sliding door made of 19 mm thk ply treated with 4mm thk app, laminate with 6 mm clear fluted glass on sliding track channel (lamp co.) with necessary door lock, handle etc. | D46: 7 | E46: 4 | F46: 1 | G46: =F46*E46*D46 -> 28 | H46: sq.ft | I46: 1800 | J46: NA
A47: 8 | B47: PARTITION | C47: a) Providing & making of kitchen 6" thk partition with 2" thk slit inside to hide out the door. made of necessary alum. Frame work and 9mm thk . ply finished in app shade of paint | D47: 7 | E47: 3 | F47: 1 | G47: =F47*E47*D47 -> 21 | H47: sq.ft | I47: 1300 | J47: NA
A49: TOTAL OF KITCHEN AREA | J49: =SUM(J38:J47) -> ₹ 486,800.00
...

Sheet INTERIOR FEES
A1: NESTURA DESIGNS (formerly SA INTERIOR SCAPES)
A2: DETAILED ESTIMATE
A3: S.NO | B3: ITEM | C3: PROPOSED DETAILS/MATERIALS | D3: UNITS | E3: GRAND TOTAL
A6: Interior Designer Fees
A7: Scope of Work: To provide 2d, 3d to client. To provide working drawings . To go for selection of materials(laminate veneer tiles décor all finishing materials) with client . To do site visits and update client as and when required. To Maintain Best Quality of work. Giving Material orders, making list of it and its procurement. Optimum material use and lesser wastage. Provide Labour Teams; get the work done as per the drawings. Rates and bill checking of material and labour. Interlinking and coordination between agencies for speedy work. To direct and maintain speed of work.
B8: Description | C8: Percentage | D8: TOTAL PROJECT COST | E8: DESIGNER FEES
B9: Designing Charges (2d drawings 3d drawings , working drawings , site visits, selection of each item needed.
A11: TOTAL AMOUNT /- | E11: 225000
B12: Interior design fees to be paid in 4 phases as follows:
A13: Phase | B13: Description | D13: Rate(Rs) | E13: AMOUNT(Rs)
A14: 1 | B14: Advance at signing designing fees | D14: 0.45 | E14: =D14*D18 -> ₹ 101,250.00
A15: 2 | B15: Design phase 1 (AFTER SELECTION) | D15: 0.25 | E15: =D15*D18 -> ₹ 56,250.00
A16: 3 | B16: Design phase 2 ( AFTER START OF PROJECT) | D16: 0.2 | E16: =D16*D18 -> ₹ 45,000.00
A17: 4 | B17: Design phase 3 (AFTER HANDOVER) | D17: 0.1 | E17: =D17*D18 -> ₹ 22,500.00
A18: 5 | B18: Designing Charges (2d drawings 3d drawings , working drawings , site visits, selection of each item needed(PUNE ). | D18: =E11 -> ₹ 225,000.00 | E18: =SUM(E14:E17) -> ₹ 225,000.00
D19: TOTAL AMOUNT ( LUMSUM) | E19: =E18 -> ₹ 225,000.00
A23: FINAL PROJECT COST (TOTAL PROJECT COST + INTERIOR DESIGN FEES) | E23: =D9+E19 -> ₹ 225,000.00

Sheet TERMS AND CONDITIONDS
A1: NESTURA DESIGNS (formerly SA INTERIOR SCAPES)
A2: MATERIAL SPECIFICATIONS AND PAYMENTS T&C
A4: ALL FURNITURE WORK WILL BE DONE IN
A6: 1 | B6: 18mm, 12mm, 6mm ply 8x4 sheet. Sliding door will be in 25mm thick blockboard
A7: 2 | B7: Laminate will be in 1 mm thick (inside-colour , outside-colour laminate)
A8: 3 | B8: Hardware, Nails , screws, Adhesives
A10: BRANDS CONSIDERED
A12: 1 | B12: Ply | C12: Basic furniture structure in high quality alternate grade plywood full face gurjan, ISO,ISI grade (Water resistance)
A13: 2 | B13: Laminate | C13: Royal Touch, Real Touch, Merino equivalent brands
A14: 3 | B14: Laminate Finishes | C14: Wood grain shine, wood grain solid, anti fingerprints, HD Gloss, Super Gloss, Textures, Scratch Resistant, PVC laminate etc
A15: 4 | B15: Glass/Mirror | C15: Plain 6mm
A16: 5 | B16: Sliding Track | C16: EBCO (soft closing) Premium
A17: 6 | B17: Adhesives | C17: Falco fix ultramarine and Falco fix EBS
A18: 7 | B18: Paint | C18: Asian, equivalent (Ceiling- luxury emulsion)
A19: 8 | B19: POP | C19: 6x4 sheets, 12MM thickness, Brand Saint Gobain-Gyproc. Gypsum sheet with aluminium metal frame by Ultra
A20: 9 | B20: Electrical Cables | C20: Polycab standard
A21: 10 | B21: Light Panels | C21: Polycab 12w
A22: 11 | B22: Kitchen Ply | C22: Waterproof, BWP
A23: 12 | B23: Kitchen Hardware | C23: EBCO soft closing hinges, Hydraulic pump, Auto hinges
... A26: 15 | B26: Curtains | C26: D'Decor or FnF
A28: PAYMENT TERMS FOR EXECUTION
A30: 1 | B30: 40% before the structural work start on site, after the finalization of 3D designs
A31: 2 | B31: 30% At the start of the carpentry stage
A32: 3 | B32: 20% At the start of wall painting
A33: 4 | B33: 10%At the start of furnishings( Before site handover (before Sofa And dinning installation)
A35: GENERAL NOTES (T&C)
A37: The above mentioned unit rates are subject to the following conditions.
A38: 1 | B38: The unit rate for any of the above items are considered as per standard of MRg material as per base rate .Any variation in the raw or design or finishing material rates.
A39: 2 | B39: Marine ply used in kitchen & toilet only. rest of all furnitures are to be made from BWR ply
A40: 3 | B40: Every room door & toilet doors has been considered with a pair of mortise hand set. Any variation in the hardware cost shall be settled as per actual purchase
A41: 4 | B41: Every room Storages has been considered with a handle upto Rs. 200/- piece. Any cost shall be settled as per actual purchase cost.
A43: GENERAL NOTES
A44: 1 | B44: The above unit rates are valid for 60 days from the date of the Bill of Quantities (BOQ). These rates are subject to changes based on inflation in material or labor costs.
A45: 2 | B45: The quantities mentioned in the BOQ are for estimation purposes only. The BOQ is subject to deviation during execution due to changes in design and site conditions.
A46: 3 | B46: The electrical costs mentioned are approximate and will be charged based on actual costs incurred during execution.
A47: 4 | B47: BMC and society permissions required for the job will be obtained by the owner. The contractor will not be responsible for obtaining these permissions.
A48: 5 | B48: Final billing will be based on actual quantities executed, and a measurement sheet will be provided, checked, and certified by both parties involved.
A49: 6 | B49: The submitted rates are unit rates, and it is assumed that these rates are agreed upon by the contractor. The amount for each item of work is calculated as per the agreed quantities and rates. These rates will apply for settling bills for any additional work executed.
A50: 7 | B50: The contractor will submit an estimate for any unforeseen costs incurred during the project. Such costs will be executed only after receiving written approval from the client. Additional work will be billed based on market rates and execution details.
A51: 8 | B51: Water and electricity will be provided free of charge by the client.
...
